<?xml version='1.0'?>
<sdf version='1.6'>
  <model name='quadrotor_payload'>
    <link name='base_link'>
      <pose frame=''>0 0 0 0 -0 0</pose>
      <inertial>
        <pose frame=''>-0.000101 0 0 0 -0 0</pose>
        <mass>1.478</mass>
        <inertia>
          <ixx>0.01152</ixx>
          <ixy>0</ixy>
          <ixz>0</ixz>
          <iyy>0.0115425</iyy>
          <iyz>0</iyz>
          <izz>0.0218225</izz>
        </inertia>
      </inertial>
      <self_collide>0</self_collide>
      <kinematic>0</kinematic>
      <velocity_decay/>
      <sensor name='sonar' type='ray'>
        <update_rate>10</update_rate>
        <ray>
          <range>
            <min>0.01</min>
            <max>3</max>
            <resolution>0.01</resolution>
          </range>
          <scan>
            <horizontal>
              <samples>3</samples>
              <min_angle>-0.349066</min_angle>
              <max_angle>0.349066</max_angle>
              <resolution>1</resolution>
            </horizontal>
            <vertical>
              <samples>3</samples>
              <min_angle>-0.349066</min_angle>
              <max_angle>0.349066</max_angle>
            </vertical>
          </scan>
        </ray>
        <plugin name='gazebo_ros_sonar_controller' filename='libhector_gazebo_ros_sonar.so'>
          <gaussianNoise>0.000</gaussianNoise>
          <topicName>sonar_height</topicName>
          <frameId>sonar_link</frameId>
          <robotNamespace>/</robotNamespace>
        </plugin>
        <pose frame=''>-0.15 0 0 3.14159 1.57079 3.14159</pose>
      </sensor>
      <gravity>1</gravity>
      <visual name='base_link_visual'>
        <pose frame=''>0 0 0 0 -0 0</pose>
        <geometry>
          <mesh>
            <scale>1 1 1</scale>
            <uri>/home/minerva/ardrone_ws/src/tum_simulator/cvg_sim_gazebo/meshes/quadrotor/quadrotor_4.dae</uri>
          </mesh>
        </geometry>
        <material>
          <script>
            <uri>__default__</uri>
            <name>__default__</name>
          </script>
          <emissive>0 0 0 1</emissive>
        </material>
        <cast_shadows>1</cast_shadows>
        <transparency>0</transparency>
      </visual>
      <visual name='base_link_fixed_joint_lump__sonar_link_visual_1'>
        <pose frame=''>-0.15 0 0 3.14159 1.57079 3.14159</pose>
        <geometry>
          <mesh>
            <scale>1 1 1</scale>
            <uri>/home/minerva/ardrone_ws/src/tum_simulator/cvg_sim_gazebo/meshes/sonar_sensor/max_sonar_ez4.dae</uri>
          </mesh>
        </geometry>
        <material>
          <script>
            <uri>__default__</uri>
            <name>__default__</name>
          </script>
          <emissive>0 0 0 1</emissive>
        </material>
        <cast_shadows>1</cast_shadows>
        <transparency>0</transparency>
      </visual>
      <collision name='base_link_collision'>
        <laser_retro>0</laser_retro>
        <max_contacts>10</max_contacts>
        <pose frame=''>0 0 0 0 -0 0</pose>
        <geometry>
          <mesh>
            <uri>/home/minerva/ardrone_ws/src/tum_simulator/cvg_sim_gazebo/meshes/quadrotor/quadrotor_4.stl</uri>
          </mesh>
        </geometry>
        <surface>
          <friction>
            <ode>
              <mu>1</mu>
              <mu2>1</mu2>
              <fdir1>0 0 0</fdir1>
              <slip1>0</slip1>
              <slip2>0</slip2>
            </ode>
            <torsional>
              <coefficient>1</coefficient>
              <patch_radius>0</patch_radius>
              <surface_radius>0</surface_radius>
              <use_patch_radius>1</use_patch_radius>
              <ode>
                <slip>0</slip>
              </ode>
            </torsional>
          </friction>
          <bounce>
            <restitution_coefficient>0</restitution_coefficient>
            <threshold>1e+06</threshold>
          </bounce>
          <contact>
            <collide_without_contact>0</collide_without_contact>
            <collide_without_contact_bitmask>1</collide_without_contact_bitmask>
            <collide_bitmask>1</collide_bitmask>
            <ode>
              <soft_cfm>0</soft_cfm>
              <soft_erp>0.2</soft_erp>
              <kp>1e+13</kp>
              <kd>1</kd>
              <max_vel>0.01</max_vel>
              <min_depth>0</min_depth>
            </ode>
            <bullet>
              <split_impulse>1</split_impulse>
              <split_impulse_penetration_threshold>-0.01</split_impulse_penetration_threshold>
              <soft_cfm>0</soft_cfm>
              <soft_erp>0.2</soft_erp>
              <kp>1e+13</kp>
              <kd>1</kd>
            </bullet>
          </contact>
        </surface>
      </collision>
      <collision name='base_link_fixed_joint_lump__sonar_link_collision_1'>
        <laser_retro>0</laser_retro>
        <max_contacts>10</max_contacts>
        <pose frame=''>-0.15 0 0 3.14159 1.57079 3.14159</pose>
        <geometry>
          <box>
            <size>0.01 0.01 0.01</size>
          </box>
        </geometry>
        <surface>
          <friction>
            <ode>
              <mu>1</mu>
              <mu2>1</mu2>
              <fdir1>0 0 0</fdir1>
              <slip1>0</slip1>
              <slip2>0</slip2>
            </ode>
            <torsional>
              <coefficient>1</coefficient>
              <patch_radius>0</patch_radius>
              <surface_radius>0</surface_radius>
              <use_patch_radius>1</use_patch_radius>
              <ode>
                <slip>0</slip>
              </ode>
            </torsional>
          </friction>
          <bounce>
            <restitution_coefficient>0</restitution_coefficient>
            <threshold>1e+06</threshold>
          </bounce>
          <contact>
            <collide_without_contact>0</collide_without_contact>
            <collide_without_contact_bitmask>1</collide_without_contact_bitmask>
            <collide_bitmask>1</collide_bitmask>
            <ode>
              <soft_cfm>0</soft_cfm>
              <soft_erp>0.2</soft_erp>
              <kp>1e+13</kp>
              <kd>1</kd>
              <max_vel>0.01</max_vel>
              <min_depth>0</min_depth>
            </ode>
            <bullet>
              <split_impulse>1</split_impulse>
              <split_impulse_penetration_threshold>-0.01</split_impulse_penetration_threshold>
              <soft_cfm>0</soft_cfm>
              <soft_erp>0.2</soft_erp>
              <kp>1e+13</kp>
              <kd>1</kd>
            </bullet>
          </contact>
        </surface>
      </collision>
    </link>


    <!-- CHANGED-->
    <link name='link_0'>
      <pose frame=''>2.4e-05 -0 -0.482558 0 -5.1e-05 1.7e-05</pose>
      <inertial>
        <mass>7.19028e-05</mass>
        <inertia>
          <ixx>4.51356e-06</ixx>
          <ixy>0</ixy>
          <ixz>0</ixz>
          <iyy>4.51356e-06</iyy>
          <iyz>0</iyz>
          <izz>7.4736e-10</izz>
        </inertia>
        <pose frame=''>0 0 0 0 -0 0</pose>
      </inertial>
      <gravity>1</gravity>
      <self_collide>0</self_collide>
      <kinematic>0</kinematic>
      <visual name='visual'>
        <pose frame=''>0 0 0 0 -0 0</pose>
        <geometry>
          <cylinder>
            <radius>0.00454307</radius>
            <length>0.867893</length>
          </cylinder>
        </geometry>
        <material>
          <lighting>1</lighting>
          <script>
            <uri>file://media/materials/scripts/gazebo.material</uri>
            <name>Gazebo/Grey</name>
          </script>
          <ambient>0.3 0.3 0.3 1</ambient>
          <diffuse>0.7 0.7 0.7 1</diffuse>
          <specular>0.01 0.01 0.01 1</specular>
          <emissive>0 0 0 1</emissive>
          <shader type='vertex'>
            <normal_map>__default__</normal_map>
          </shader>
        </material>
        <cast_shadows>1</cast_shadows>
        <transparency>0</transparency>
      </visual>
      <collision name='collision'>
        <laser_retro>0</laser_retro>
        <max_contacts>10</max_contacts>
        <pose frame=''>0 0 0 0 -0 0</pose>
        <geometry>
          <cylinder>
            <radius>0.004543</radius>
            <length>0.867893</length>
          </cylinder>
        </geometry>
        <surface>
          <friction>
            <ode>
              <mu>1</mu>
              <mu2>1</mu2>
              <fdir1>0 0 0</fdir1>
              <slip1>0</slip1>
              <slip2>0</slip2>
            </ode>
            <torsional>
              <coefficient>1</coefficient>
              <patch_radius>0</patch_radius>
              <surface_radius>0</surface_radius>
              <use_patch_radius>1</use_patch_radius>
              <ode>
                <slip>0</slip>
              </ode>
            </torsional>
          </friction>
          <bounce>
            <restitution_coefficient>0</restitution_coefficient>
            <threshold>1e+06</threshold>
          </bounce>
          <contact>
            <collide_without_contact>0</collide_without_contact>
            <collide_without_contact_bitmask>1</collide_without_contact_bitmask>
            <collide_bitmask>1</collide_bitmask>
            <ode>
              <soft_cfm>0</soft_cfm>
              <soft_erp>0.2</soft_erp>
              <kp>1e+13</kp>
              <kd>1</kd>
              <max_vel>0.01</max_vel>
              <min_depth>0</min_depth>
            </ode>
            <bullet>
              <split_impulse>1</split_impulse>
              <split_impulse_penetration_threshold>-0.01</split_impulse_penetration_threshold>
              <soft_cfm>0</soft_cfm>
              <soft_erp>0.2</soft_erp>
              <kp>1e+13</kp>
              <kd>1</kd>
            </bullet>
          </contact>
        </surface>
      </collision>
    </link>
    <link name='link_1'>
      <pose frame=''>5.1e-05 0 -0.98437 0 -5.1e-05 1.7e-05</pose>
      <inertial>
        <mass>0.00471499</mass>
        <inertia>
          <ixx>1.32577e-05</ixx>
          <ixy>0</ixy>
          <ixz>0</ixz>
          <iyy>1.32577e-05</iyy>
          <iyz>0</iyz>
          <izz>1.32577e-05</izz>
        </inertia>
        <pose frame=''>0 0 0 0 -0 0</pose>
      </inertial>
      <visual name='visual'>
        <pose frame=''>0 0 0 0 -0 0</pose>
        <geometry>
          <sphere>
            <radius>0.083842</radius>
          </sphere>
        </geometry>
        <material>
          <lighting>1</lighting>
          <script>
            <uri>file://media/materials/scripts/gazebo.material</uri>
            <name>Gazebo/Grey</name>
          </script>
          <ambient>0.3 0.3 0.3 1</ambient>
          <diffuse>0.7 0.7 0.7 1</diffuse>
          <specular>0.01 0.01 0.01 1</specular>
          <emissive>0 0 0 1</emissive>
        </material>
        <cast_shadows>1</cast_shadows>
        <transparency>0</transparency>
      </visual>
      <collision name='collision'>
        <laser_retro>0</laser_retro>
        <max_contacts>10</max_contacts>
        <pose frame=''>0 0 0 0 -0 0</pose>
        <geometry>
          <sphere>
            <radius>0.083842</radius>
          </sphere>
        </geometry>
        <surface>
          <friction>
            <ode>
              <mu>1</mu>
              <mu2>1</mu2>
              <fdir1>0 0 0</fdir1>
              <slip1>0</slip1>
              <slip2>0</slip2>
            </ode>
            <torsional>
              <coefficient>1</coefficient>
              <patch_radius>0</patch_radius>
              <surface_radius>0</surface_radius>
              <use_patch_radius>1</use_patch_radius>
              <ode>
                <slip>0</slip>
              </ode>
            </torsional>
          </friction>
          <bounce>
            <restitution_coefficient>0</restitution_coefficient>
            <threshold>1e+06</threshold>
          </bounce>
          <contact>
            <collide_without_contact>0</collide_without_contact>
            <collide_without_contact_bitmask>1</collide_without_contact_bitmask>
            <collide_bitmask>1</collide_bitmask>
            <ode>
              <soft_cfm>0</soft_cfm>
              <soft_erp>0.2</soft_erp>
              <kp>1e+13</kp>
              <kd>1</kd>
              <max_vel>0.01</max_vel>
              <min_depth>0</min_depth>
            </ode>
            <bullet>
              <split_impulse>1</split_impulse>
              <split_impulse_penetration_threshold>-0.01</split_impulse_penetration_threshold>
              <soft_cfm>0</soft_cfm>
              <soft_erp>0.2</soft_erp>
              <kp>1e+13</kp>
              <kd>1</kd>
            </bullet>
          </contact>
        </surface>
      </collision>
    </link>
    <joint name='string2drone' type='universal'>
      <parent>base_link</parent>
      <child>link_0</child>
      <pose frame=''>0 0 0.42 0 -0 0</pose>
      <axis>
        <xyz>1 0 0</xyz>
        <use_parent_model_frame>0</use_parent_model_frame>
        <limit>
          <lower>-1.79769e+308</lower>
          <upper>1.79769e+308</upper>
          <effort>-1</effort>
          <velocity>-1</velocity>
        </limit>
        <dynamics>
          <spring_reference>0</spring_reference>
          <spring_stiffness>0</spring_stiffness>
          <damping>0</damping>
          <friction>0</friction>
        </dynamics>
      </axis>
      <axis2>
        <xyz>0 1 0</xyz>
        <use_parent_model_frame>0</use_parent_model_frame>
        <dynamics>
          <spring_reference>0</spring_reference>
          <spring_stiffness>0</spring_stiffness>
          <damping>0</damping>
          <friction>0</friction>
        </dynamics>
        <limit>
          <lower>-1.79769e+308</lower>
          <upper>1.79769e+308</upper>
          <effort>-1</effort>
          <velocity>-1</velocity>
        </limit>
      </axis2>
      <physics>
        <ode>
          <limit>
            <cfm>0</cfm>
            <erp>0.2</erp>
          </limit>
          <suspension>
            <cfm>0</cfm>
            <erp>0.2</erp>
          </suspension>
        </ode>
      </physics>
    </joint>
    <joint name='payload2string' type='universal'>
      <parent>link_0</parent>
      <child>link_1</child>
      <pose frame=''>0 0 0 0 -0 0</pose>
      <axis>
        <xyz>1 0 0</xyz>
        <use_parent_model_frame>0</use_parent_model_frame>
        <limit>
          <lower>-1.79769e+308</lower>
          <upper>1.79769e+308</upper>
          <effort>-1</effort>
          <velocity>-1</velocity>
        </limit>
        <dynamics>
          <spring_reference>0</spring_reference>
          <spring_stiffness>0</spring_stiffness>
          <damping>0</damping>
          <friction>0</friction>
        </dynamics>
      </axis>
      <axis2>
        <xyz>0 1 0</xyz>
        <use_parent_model_frame>0</use_parent_model_frame>
        <dynamics>
          <spring_reference>0</spring_reference>
          <spring_stiffness>0</spring_stiffness>
          <damping>0</damping>
          <friction>0</friction>
        </dynamics>
        <limit>
          <lower>-1.79769e+308</lower>
          <upper>1.79769e+308</upper>
          <effort>-1</effort>
          <velocity>-1</velocity>
        </limit>
      </axis2>
      <physics>
        <ode>
          <limit>
            <cfm>0</cfm>
            <erp>0.2</erp>
          </limit>
          <suspension>
            <cfm>0</cfm>
            <erp>0.2</erp>
          </suspension>
        </ode>
      </physics>
    </joint>
    <!-- CHANGED-->



    <static>0</static>
    <allow_auto_disable>1</allow_auto_disable>
    <plugin name='quadrotor_baro_sim' filename='libhector_gazebo_ros_baro.so'>
      <alwaysOn>true</alwaysOn>
      <updateRate>10.0</updateRate>
      <bodyName>base_link</bodyName>
      <topicName>pressure_height</topicName>
      <altimeterTopicName>altimeter</altimeterTopicName>
      <offset>0</offset>
      <drift>0.1</drift>
      <gaussianNoise>0.5</gaussianNoise>
      <robotNamespace>/</robotNamespace>
    </plugin>
    <plugin name='quadrotor_gps_sim' filename='libhector_gazebo_ros_gps.so'>
      <alwaysOn>true</alwaysOn>
      <updateRate>4.0</updateRate>
      <bodyName>base_link</bodyName>
      <topicName>fix</topicName>
      <velocityTopicName>fix_velocity</velocityTopicName>
      <drift>5.0 5.0 5.0</drift>
      <gaussianNoise>0.1 0.1 0.1</gaussianNoise>
      <velocityDrift>0 0 0</velocityDrift>
      <velocityGaussianNoise>0.1 0.1 0.1</velocityGaussianNoise>
      <robotNamespace>/</robotNamespace>
    </plugin>
    <plugin name='quadrotor_groundtruth_sim' filename='libgazebo_ros_p3d.so'>
      <alwaysOn>true</alwaysOn>
      <updateRate>100.0</updateRate>
      <bodyName>base_link</bodyName>
      <topicName>ground_truth/state</topicName>
      <gaussianNoise>0.0</gaussianNoise>
      <frameName>map</frameName>
      <robotNamespace>/</robotNamespace>
    </plugin>
    <plugin name='quadrotor_imu_sim' filename='libhector_gazebo_ros_imu.so'>
      <alwaysOn>true</alwaysOn>
      <updateRate>100.0</updateRate>
      <bodyName>base_link</bodyName>
      <frameId>ardrone_base_link</frameId>
      <topicName>/ardrone/imu</topicName>
      <rpyOffsets>0 0 0</rpyOffsets>
      <gaussianNoise>0</gaussianNoise>
      <accelDrift>0.5 0.5 0.5</accelDrift>
      <accelGaussianNoise>0.35 0.35 0.3</accelGaussianNoise>
      <rateDrift>0.0 0.0 0.0</rateDrift>
      <rateGaussianNoise>0.00 0.00 0.00</rateGaussianNoise>
      <headingDrift>0.0</headingDrift>
      <headingGaussianNoise>0.00</headingGaussianNoise>
      <robotNamespace>/</robotNamespace>
    </plugin>
    <plugin name='quadrotor_magnetic_sim' filename='libhector_gazebo_ros_magnetic.so'>
      <alwaysOn>true</alwaysOn>
      <updateRate>10.0</updateRate>
      <bodyName>base_link</bodyName>
      <topicName>magnetic</topicName>
      <offset>0 0 0</offset>
      <drift>0.0 0.0 0.0</drift>
      <gaussianNoise>1.3e-2 1.3e-2 1.3e-2</gaussianNoise>
      <robotNamespace>/</robotNamespace>
    </plugin>
    <plugin name='quadrotor_simple_controller' filename='libhector_gazebo_quadrotor_simple_controller.so'>
      <alwaysOn>true</alwaysOn>
      <updateRate>0.0</updateRate>
      <bodyName>base_link</bodyName>
      <stateTopic>ground_truth/state</stateTopic>
      <imuTopic>ardrone/imu</imuTopic>
      <topicName>cmd_vel</topicName>
      <rollpitchProportionalGain>10.0</rollpitchProportionalGain>
      <rollpitchDifferentialGain>5.0</rollpitchDifferentialGain>
      <rollpitchLimit>0.5</rollpitchLimit>
      <yawProportionalGain>2.0</yawProportionalGain>
      <yawDifferentialGain>1.0</yawDifferentialGain>
      <yawLimit>1.5</yawLimit>
      <velocityXYProportionalGain>5.0</velocityXYProportionalGain>
      <velocityXYDifferentialGain>1.0</velocityXYDifferentialGain>
      <velocityXYLimit>2</velocityXYLimit>
      <velocityZProportionalGain>5.0</velocityZProportionalGain>
      <velocityZDifferentialGain>1.0</velocityZDifferentialGain>
      <velocityZLimit>0.5</velocityZLimit>
      <maxForce>30</maxForce>
      <motionSmallNoise>0.05</motionSmallNoise>
      <motionDriftNoise>0.03</motionDriftNoise>
      <motionDriftNoiseTime>5.0</motionDriftNoiseTime>
      <robotNamespace>/</robotNamespace>
    </plugin>
    <plugin name='quadrotor_state_controller' filename='libhector_gazebo_quadrotor_state_controller.so'>
      <alwaysOn>true</alwaysOn>
      <updateRate>0.0</updateRate>
      <bodyName>base_link</bodyName>
      <stateTopic>ground_truth/state</stateTopic>
      <imuTopic>ardrone/imu</imuTopic>
      <sonarTopic>sonar_height</sonarTopic>
      <topicName>cmd_vel</topicName>
      <robotNamespace>/</robotNamespace>
    </plugin>
  </model>
</sdf>
